Workbook
Name _1Excel_BuiltIn_Print_Area_1_1: "$#REF!.$A$2:$C$35"
Name _MAT2010: #REF!
Name A: #REF!
Name A_2: "$#REF!.$A$4:$U$97"
Name A_5: "$#REF!.$A$4:$U$97"
Name A_6: "$#REF!.$A$4:$U$97"
Name ADELCA_MALLAELECTROSOLDADA_6x2.4m: #REF!
Name ALUMINIO_PLACA: #REF!
Name ARANDELA_PLANA: #REF!
Name ARANDELA_PRESIÓN: #REF!
Name ARANDELA_RELLENO: #REF!
Name area2011: #REF!
Name AREA2014: #REF!
Name AREA2014A: #REF!
Name AREA2014B: #REF!
Name Arriostramientos_2C: 'Lista de Articulos'!$B$2:$B$1048576
Name Arriostramientos_4PL: 'Lista de Articulos'!$C$2:$C$1048576
Name Arriostramientos_H_I: 'Lista de Articulos'!$D$2:$D$1048576
Name BAJANTE_TOOL: #REF!
Name BAJANTES_PVC: #REF!
Name CANAL: #REF!
Name CODO_90ºPVC: #REF!
Name CODO_SCH40: #REF!
Name CODOS_45ºPVC: #REF!
Name CODOS_SCH40: #REF!
Name COT: [1]DATOS!$A$3:$G$647
Name CUBIERTA_A792: #REF!
Name CUBIERTA_INYECTADA: #REF!
Name CUMBRERO: #REF!
Name e: #REF!
Name EJE_TRANSMISIÓN_SAE1018: #REF!
Name Excel_BuiltIn_Print_Area: "$#REF!.$A$47:$I$92"
Name Excel_BuiltIn_Print_Area_2: "$#REF!.$A$39:$I$78"
Name Excel_BuiltIn_Print_Area_4: "$#REF!.$#REF!$#REF!:$#REF!$#REF!"
Name Excel_BuiltIn_Print_Titles: "$#REF!.$A$6:$IV$7"
Name Excel_BuiltIn_Print_Titles_2: "$#REF!.$A$7:$IV$8"
Name Excel_BuiltIn_Print_Titles_5: "$#REF!.$A$7:$IV$8"
Name Excel_BuiltIn_Print_Titles_6: "$#REF!.$A$7:$IV$8"
Name GALPON: #REF!
Name HEA_laminado: #REF!
Name HEB_laminado: #REF!
Name HERRAJE: #REF!
Name HGF: #REF!
Name HILTI: #REF!
Name HOJAINT: #REF!
Name IPE_laminado: #REF!
Name IPN_laminado: #REF!
Name LI: #REF!
Name LISTAM: #REF!
Name LISTAMAT: [2]DATOS!$A$3:$G$647
Name ListaPosicion: 'Lista de Articulos'!$A$2:$A$1048576
Name ListaPosicionPrin: 'ORDENES DE FABRICACION'!$E$6
Name LISTMAT: #REF!
Name LISTMAT_2: "$#REF!.$A$9:$Z$226"
Name LISTMAT_5: "$#REF!.$A$9:$Z$226"
Name LISTMAT_6: "$#REF!.$A$9:$Z$226"
Name LISTMATERILES: #REF!
Name MALLA_EXPANDIDA_PARA_TORRES: #REF!
Name MATER20011: #REF!
Name PARAORDENAR: #REF!

Sheet ORDENES DE FABRICACION
A1: FACTOR
A2: F. ESTRUCTURA | B2: 1
A3: F PERNOS | B3: 1
C4: ESTRUCTURA PRINCIPAL
A5: SERIE | B5: ENTREGA | C5: ITEM | D5: CODIGO | E5: POSICIÓN | F5: SECCION | G5: TEKLA | H5: PESO U | I5: CODIGO EKON | J5: LARGO ( mm ) | K5: ANCHO ( mm ) | L5: AREA TOTAL m2 | M5: PINTURA UNITARIA m2 | N5: PINTURA TOTAL m2 | O5: CANT ( U ) | P5: CANT TOTAL | Q5: PESO PERF ( Kg ) | R5: PESO UNID ( Kg ) | S5: PESO TOTAL (kg) | T5: PESO T ( Kg ) | U5: Peso/ml (Kg/ml) | V5: CATEGORIA (L, M, P, EP) | W5: DIST ENTRE C / C | X5: CODIGO DE PERF | Y5: ø DE PERFORACION | Z5: DESPUNTE IZQ. | AA5: DESPUNTE DER. | AB5: PERF A | AC5: PERF B | AD5: PERF C | AE5: PERF D | AF5: PERF E | AG5: PERF G | AH5: PERF Z | AI5: PERF F | AJ5: ESPECIFICACION DE MATERIAL | AK5: TERMINADO | AL5: PLANO | AM5: OBSERVACIONES
B6: 1 | C6: 1 | D6: M1 | E6: PLACA | F6: =F7 -> PLE 12mm | G6: =G7 -> PL12X121 | J6: =MAX(J7) -> 372 | N6: 0.1 | O6: 26 | P6: =O6*TOTALES!$A$1 -> 26 | Q6: =+R6 -> 4.2401304 | R6: =SUM(R7) -> 4.2401304 | T6: =+R6*P6 -> 110.24339 | U6: =R6/(J6/1000) -> 11.3982 | V6: =IF(U6>100,"EXTRAPESADO",IF(U6<=100,IF(U6>=60,"PESADO",IF(U6<60,IF(U6>=30,"MEDIANO","LIVIANO"))))) -> LIVIANO | AJ6: =AJ7 -> A36 | AL6: =D6 -> M1 | AM6: ;
A7: 687 | B7: =B6 -> 1 | D7: M1 | E7: PLACA | F7: =IF(A7=0,"SERIE",+VLOOKUP(A7,[3]!AREA2014A,3)) -> PLE 12mm | G7: PL12X121 | H7: =IF(A7=0,"PESOU",+VLOOKUP(A7,[3]!AREA2014A,4))*$B$2 -> 94.2 | I7: =IF(A7=0,"CODIGO", +VLOOKUP(A7,[3]!AREA2014A,13)) -> 12.54.52.390.00 | J7: 372 | K7: 121 | L7: 0.1 | M7: 2.41 | O7: 1 | P7: =O7*$P$6 -> 26 | Q7: =IF(K7="",+H7/1000*J7,+H7/1000*J7/1000*K7) -> 4.2401304 | R7: =+Q7*O7 -> 4.2401304 | S7: =+Q7*P7 -> 110.24339 | V7: =IF(U6>100,"EXTRAPESADO",IF(U6<=100,IF(U6>=60,"PESADO",IF(U6<60,IF(U6>=30,"MEDIANO","LIVIANO"))))) -> LIVIANO | AJ7: =IF(A7=0,"NORMA", +VLOOKUP(A7,[3]!AREA2014A,15)) -> A36 | AL7: =AL6 -> M1 | AM7: ;
B8: 1 | C8: 2 | D8: M3 | E8: PLATE | F8: =F9 -> PLE 12mm | G8: =G9 -> PL12X121 | J8: =MAX(J9) -> 372 | N8: 0.1 | O8: 2 | P8: =O8*TOTALES!$A$1 -> 2 | Q8: =+R8 -> 4.2401304 | R8: =SUM(R9) -> 4.2401304 | T8: =+R8*P8 -> 8.4802608 | U8: =R8/(J8/1000) -> 11.3982 | V8: =IF(U8>100,"EXTRAPESADO",IF(U8<=100,IF(U8>=60,"PESADO",IF(U8<60,IF(U8>=30,"MEDIANO","LIVIANO"))))) -> LIVIANO | AJ8: =AJ9 -> A36 | AL8: =D8 -> M3 | AM8: ;
A9: 687 | B9: =B8 -> 1 | D9: M3 | E9: PLATE | F9: =IF(A9=0,"SERIE",+VLOOKUP(A9,[3]!AREA2014A,3)) -> PLE 12mm | G9: PL12X121 | H9: =IF(A9=0,"PESOU",+VLOOKUP(A9,[3]!AREA2014A,4))*$B$2 -> 94.2 | I9: =IF(A9=0,"CODIGO", +VLOOKUP(A9,[3]!AREA2014A,13)) -> 12.54.52.390.00 | J9: 372 | K9: 121 | L9: 0.1 | M9: 0.2 | O9: 1 | P9: =O9*$P$8 -> 2 | Q9: =IF(K9="",+H9/1000*J9,+H9/1000*J9/1000*K9) -> 4.2401304 | R9: =+Q9*O9 -> 4.2401304 | S9: =+Q9*P9 -> 8.4802608 | V9: =IF(U8>100,"EXTRAPESADO",IF(U8<=100,IF(U8>=60,"PESADO",IF(U8<60,IF(U8>=30,"MEDIANO","LIVIANO"))))) -> LIVIANO | AJ9: =IF(A9=0,"NORMA", +VLOOKUP(A9,[3]!AREA2014A,15)) -> A36 | AL9: =AL8 -> M3 | AM9: ;
B10: 1 | C10: 3 | D10: TCL1 | E10: COLUMNA - HEB 300 | F10: =F11 -> PLE 12mm | G10: =G11 -> HEB300 | J10: =MAX(J11:J20) -> 4791 | N10: 10.8 | O10: 1 | P10: =O10*TOTALES!$A$1 -> 1 | Q10: =+R10 -> 730.64032 | R10: =SUM(R11:R20) -> 730.64032 | T10: =+R10*P10 -> 730.64032 | U10: =R10/(J10/1000) -> 152.50268 | V10: =IF(U10>100,"EXTRAPESADO",IF(U10<=100,IF(U10>=60,"PESADO",IF(U10<60,IF(U10>=30,"MEDIANO","LIVIANO"))))) -> EXTRAPESADO | AJ10: =AJ11 -> A36 | AL10: =D10 -> TCL1 | AM10: ;
A11: 687 | B11: =B10 -> 1 | D11: TCL1 | E11: ALMA | F11: =IF(A11=0,"SERIE",+VLOOKUP(A11,[3]!AREA2014A,3)) -> PLE 12mm | G11: HEB300 | H11: =IF(A11=0,"PESOU",+VLOOKUP(A11,[3]!AREA2014A,4))*$B$2 -> 94.2 | I11: =IF(A11=0,"CODIGO", +VLOOKUP(A11,[3]!AREA2014A,13)) -> 12.54.52.390.00 | J11: 4791 | K11: =300-40 -> 260 | L11: 8.548 | M11: 8.55 | O11: 1 | P11: =O11*$P$10 -> 1 | Q11: =IF(K11="",+H11/1000*J11,+H11/1000*J11/1000*K11) -> 117.34117 | R11: =+Q11*O11 -> 117.34117 | S11: =+Q11*P11 -> 117.34117 | V11: =IF(U10>100,"EXTRAPESADO",IF(U10<=100,IF(U10>=60,"PESADO",IF(U10<60,IF(U10>=30,"MEDIANO","LIVIANO"))))) -> EXTRAPESADO | AJ11: =IF(A11=0,"NORMA", +VLOOKUP(A11,[3]!AREA2014A,15)) -> A36 | AL11: =AL10 -> TCL1 | AM11: ;
A12: 693 | B12: =B11 -> 1 | D12: TCL1 | E12: PATIN | F12: =IF(A12=0,"SERIE",+VLOOKUP(A12,[3]!AREA2014A,3)) -> PLE 20mm | G12: HEB300 | H12: =IF(A12=0,"PESOU",+VLOOKUP(A12,[3]!AREA2014A,4))*$B$2 -> 157 | I12: =IF(A12=0,"CODIGO", +VLOOKUP(A12,[3]!AREA2014A,13)) -> 12.54.52.470.03 | J12: 4791 | K12: 300 | L12: 8.548 | M12: 8.55 | O12: 2 | P12: =O12*$P$10 -> 2 | Q12: =IF(K12="",+H12/1000*J12,+H12/1000*J12/1000*K12) -> 225.6561 | R12: =+Q12*O12 -> 451.3122 | S12: =+Q12*P12 -> 451.3122 | V12: =IF(U11>100,"EXTRAPESADO",IF(U11<=100,IF(U11>=60,"PESADO",IF(U11<60,IF(U11>=30,"MEDIANO","LIVIANO"))))) -> LIVIANO | AJ12: =IF(A12=0,"NORMA", +VLOOKUP(A12,[3]!AREA2014A,15)) -> A36 | AL12: =AL11 -> TCL1 | AM12: ;
A13: 979 | B13: =B10 -> 1 | D13: p1 | E13: PLACA | F13: =IF(A13=0,"SERIE",+VLOOKUP(A13,[3]!AREA2014A,3)) -> PLE 15mm | G13: PL10X144 | H13: =IF(A13=0,"PESOU",+VLOOKUP(A13,[3]!AREA2014A,4))*$B$2 -> 117.75 | I13: =IF(A13=0,"CODIGO", +VLOOKUP(A13,[3]!AREA2014A,13)) -> 12.54.52.420.00 | J13: 149 | K13: 144 | L13: 0.033 | M13: 0.07 | O13: 2 | P13: =O13*$P$10 -> 2 | Q13: =IF(K13="",+H13/1000*J13,+H13/1000*J13/1000*K13) -> 2.526444 | R13: =+Q13*O13 -> 5.052888 | S13: =+Q13*P13 -> 5.052888 | V13: =IF(U10>100,"EXTRAPESADO",IF(U10<=100,IF(U10>=60,"PESADO",IF(U10<60,IF(U10>=30,"MEDIANO","LIVIANO"))))) -> EXTRAPESADO | AJ13: =IF(A13=0,"NORMA", +VLOOKUP(A13,[3]!AREA2014A,15)) -> A572 G50 | AL13: =AL11 -> TCL1 | AM13: ;
A14: 693 | B14: =B10 -> 1 | D14: pb1 | E14: PLACA BASE | F14: =IF(A14=0,"SERIE",+VLOOKUP(A14,[3]!AREA2014A,3)) -> PLE 20mm | G14: PL20X460 | H14: =IF(A14=0,"PESOU",+VLOOKUP(A14,[3]!AREA2014A,4))*$B$2 -> 157 | I14: =IF(A14=0,"CODIGO", +VLOOKUP(A14,[3]!AREA2014A,13)) -> 12.54.52.470.03 | J14: 460 | K14: 460 | L14: 0.46 | M14: 0.46 | O14: 1 | P14: =O14*$P$10 -> 1 | Q14: =IF(K14="",+H14/1000*J14,+H14/1000*J14/1000*K14) -> 33.2212 | R14: =+Q14*O14 -> 33.2212 | S14: =+Q14*P14 -> 33.2212 | V14: =IF(U10>100,"EXTRAPESADO",IF(U10<=100,IF(U10>=60,"PESADO",IF(U10<60,IF(U10>=30,"MEDIANO","LIVIANO"))))) -> EXTRAPESADO | AJ14: =IF(A14=0,"NORMA", +VLOOKUP(A14,[3]!AREA2014A,15)) -> A36 | AL14: =AL13 -> TCL1 | AM14: ;
A15: 693 | B15: =B10 -> 1 | D15: pl7 | E15: ENDPLATE_1 | F15: =IF(A15=0,"SERIE",+VLOOKUP(A15,[3]!AREA2014A,3)) -> PLE 20mm | G15: PL20X250 | H15: =IF(A15=0,"PESOU",+VLOOKUP(A15,[3]!AREA2014A,4))*$B$2 -> 157 | I15: =IF(A15=0,"CODIGO", +VLOOKUP(A15,[3]!AREA2014A,13)) -> 12.54.52.470.03 | J15: 350 | K15: 250 | L15: 0.199 | M15: 0.2 | O15: 1 | P15: =O15*$P$10 -> 1 | Q15: =IF(K15="",+H15/1000*J15,+H15/1000*J15/1000*K15) -> 13.7375 | R15: =+Q15*O15 -> 13.7375 | S15: =+Q15*P15 -> 13.7375 | V15: =IF(U10>100,"EXTRAPESADO",IF(U10<=100,IF(U10>=60,"PESADO",IF(U10<60,IF(U10>=30,"MEDIANO","LIVIANO"))))) -> EXTRAPESADO | AJ15: =IF(A15=0,"NORMA", +VLOOKUP(A15,[3]!AREA2014A,15)) -> A36 | AL15: =AL14 -> TCL1 | AM15: ;
A16: 693 | B16: =B10 -> 1 | D16: pl8 | E16: PLACA | F16: =IF(A16=0,"SERIE",+VLOOKUP(A16,[3]!AREA2014A,3)) -> PLE 20mm | G16: PL20X259 | H16: =IF(A16=0,"PESOU",+VLOOKUP(A16,[3]!AREA2014A,4))*$B$2 -> 157 | I16: =IF(A16=0,"CODIGO", +VLOOKUP(A16,[3]!AREA2014A,13)) -> 12.54.52.470.03 | J16: 345 | K16: 259 | L16: 0.199 | M16: 0.8 | O16: 4 | P16: =O16*$P$10 -> 4 | Q16: =IF(K16="",+H16/1000*J16,+H16/1000*J16/1000*K16) -> 14.028735 | R16: =+Q16*O16 -> 56.11494 | S16: =+Q16*P16 -> 56.11494 | V16: =IF(U10>100,"EXTRAPESADO",IF(U10<=100,IF(U10>=60,"PESADO",IF(U10<60,IF(U10>=30,"MEDIANO","LIVIANO"))))) -> EXTRAPESADO | AJ16: =IF(A16=0,"NORMA", +VLOOKUP(A16,[3]!AREA2014A,15)) -> A36 | AL16: =AL15 -> TCL1 | AM16: ;
A17: 693 | B17: =B10 -> 1 | D17: pl9 | E17: PLACA | F17: =IF(A17=0,"SERIE",+VLOOKUP(A17,[3]!AREA2014A,3)) -> PLE 20mm | G17: PL20X145 | H17: =IF(A17=0,"PESOU",+VLOOKUP(A17,[3]!AREA2014A,4))*$B$2 -> 157 | I17: =IF(A17=0,"CODIGO", +VLOOKUP(A17,[3]!AREA2014A,13)) -> 12.54.52.470.03 | J17: 258 | K17: 145 | L17: 0.089 | M17: 0.36 | O17: 4 | P17: =O17*$P$10 -> 4 | Q17: =IF(K17="",+H17/1000*J17,+H17/1000*J17/1000*K17) -> 5.87337 | R17: =+Q17*O17 -> 23.49348 | S17: =+Q17*P17 -> 23.49348 | V17: =IF(U10>100,"EXTRAPESADO",IF(U10<=100,IF(U10>=60,"PESADO",IF(U10<60,IF(U10>=30,"MEDIANO","LIVIANO"))))) -> EXTRAPESADO | AJ17: =IF(A17=0,"NORMA", +VLOOKUP(A17,[3]!AREA2014A,15)) -> A36 | AL17: =AL16 -> TCL1 | AM17: ;
A18: 687 | B18: =B10 -> 1 | D18: pl10 | E18: PLACA | F18: =IF(A18=0,"SERIE",+VLOOKUP(A18,[3]!AREA2014A,3)) -> PLE 12mm | G18: PL12X300 | H18: =IF(A18=0,"PESOU",+VLOOKUP(A18,[3]!AREA2014A,4))*$B$2 -> 94.2 | I18: =IF(A18=0,"CODIGO", +VLOOKUP(A18,[3]!AREA2014A,13)) -> 12.54.52.390.00 | J18: 345 | K18: 300 | L18: 0.219 | M18: 0.22 | O18: 1 | P18: =O18*$P$10 -> 1 | Q18: =IF(K18="",+H18/1000*J18,+H18/1000*J18/1000*K18) -> 9.7497 | R18: =+Q18*O18 -> 9.7497 | S18: =+Q18*P18 -> 9.7497 | V18: =IF(U10>100,"EXTRAPESADO",IF(U10<=100,IF(U10>=60,"PESADO",IF(U10<60,IF(U10>=30,"MEDIANO","LIVIANO"))))) -> EXTRAPESADO | AJ18: =IF(A18=0,"NORMA", +VLOOKUP(A18,[3]!AREA2014A,15)) -> A36 | AL18: =AL17 -> TCL1 | AM18: ;
A19: 693 | B19: =B10 -> 1 | D19: pl11 | E19: ENDPLATE_1 | F19: =IF(A19=0,"SERIE",+VLOOKUP(A19,[3]!AREA2014A,3)) -> PLE 20mm | G19: PL20X250 | H19: =IF(A19=0,"PESOU",+VLOOKUP(A19,[3]!AREA2014A,4))*$B$2 -> 157 | I19: =IF(A19=0,"CODIGO", +VLOOKUP(A19,[3]!AREA2014A,13)) -> 12.54.52.470.03 | J19: 310 | K19: 250 | L19: 0.177 | M19: 0.18 | O19: 1 | P19: =O19*$P$10 -> 1 | Q19: =IF(K19="",+H19/1000*J19,+H19/1000*J19/1000*K19) -> 12.1675 | R19: =+Q19*O19 -> 12.1675 | S19: =+Q19*P19 -> 12.1675 | V19: =IF(U10>100,"EXTRAPESADO",IF(U10<=100,IF(U10>=60,"PESADO",IF(U10<60,IF(U10>=30,"MEDIANO","LIVIANO"))))) -> EXTRAPESADO | AJ19: =IF(A19=0,"NORMA", +VLOOKUP(A19,[3]!AREA2014A,15)) -> A36 | AL19: =AL18 -> TCL1 | AM19: ;
A20: 687 | B20: =B10 -> 1 | D20: pl12 | E20: PLACA | F20: =IF(A20=0,"SERIE",+VLOOKUP(A20,[3]!AREA2014A,3)) -> PLE 12mm | G20: PL12X260 | H20: =IF(A20=0,"PESOU",+VLOOKUP(A20,[3]!AREA2014A,4))*$B$2 -> 94.2 | I20: =IF(A20=0,"CODIGO", +VLOOKUP(A20,[3]!AREA2014A,13)) -> 12.54.52.390.00 | J20: 345 | K20: 260 | L20: 0.19 | M20: 0.19 | O20: 1 | P20: =O20*$P$10 -> 1 | Q20: =IF(K20="",+H20/1000*J20,+H20/1000*J20/1000*K20) -> 8.44974 | R20: =+Q20*O20 -> 8.44974 | S20: =+Q20*P20 -> 8.44974 | V20: =IF(U10>100,"EXTRAPESADO",IF(U10<=100,IF(U10>=60,"PESADO",IF(U10<60,IF(U10>=30,"MEDIANO","LIVIANO"))))) -> EXTRAPESADO | AJ20: =IF(A20=0,"NORMA", +VLOOKUP(A20,[3]!AREA2014A,15)) -> A36 | AL20: =AL19 -> TCL1 | AM20: ;
B21: 1 | C21: 4 | D21: TCL2 | E21: COLUMNA - HEB200 | F21: =F22 -> PLE 10mm | G21: =G22 -> HEB200 | J21: =MAX(J22:J25) -> 5076 | N21: 6.4 | O21: 1 | P21: =O21*TOTALES!$A$1 -> 1 | Q21: =+R21 -> 345.09291 | R21: =SUM(R22:R25) -> 345.09291 | T21: =+R21*P21 -> 345.09291 | U21: =R21/(J21/1000) -> 67.985206 | V21: =IF(U21>100,"EXTRAPESADO",IF(U21<=100,IF(U21>=60,"PESADO",IF(U21<60,IF(U21>=30,"MEDIANO","LIVIANO"))))) -> PESADO | AJ21: =AJ22 -> A36 | AL21: =D21 -> TCL2 | AM21: ;
A22: 686 | B22: =B21 -> 1 | D22: TCL2 | E22: ALMA | F22: =IF(A22=0,"SERIE",+VLOOKUP(A22,[3]!AREA2014A,3)) -> PLE 10mm | G22: HEB200 | H22: =IF(A22=0,"PESOU",+VLOOKUP(A22,[3]!AREA2014A,4))*$B$2 -> 78.5 | I22: =IF(A22=0,"CODIGO", +VLOOKUP(A22,[3]!AREA2014A,13)) -> 12.54.52.370.07 | J22: 5076 | K22: =200-30 -> 170 | L22: 6.015 | M22: 6.02 | O22: 1 | P22: =O22*$P$21 -> 1 | Q22: =IF(K22="",+H22/1000*J22,+H22/1000*J22/1000*K22) -> 67.73922 | R22: =+Q22*O22 -> 67.73922 | S22: =+Q22*P22 -> 67.73922 | V22: =IF(U21>100,"EXTRAPESADO",IF(U21<=100,IF(U21>=60,"PESADO",IF(U21<60,IF(U21>=30,"MEDIANO","LIVIANO"))))) -> PESADO | AJ22: =IF(A22=0,"NORMA", +VLOOKUP(A22,[3]!AREA2014A,15)) -> A36 | AL22: =AL21 -> TCL2 | AM22: ;
A23: 689 | B23: =B22 -> 1 | D23: TCL2 | E23: PATIN | F23: =IF(A23=0,"SERIE",+VLOOKUP(A23,[3]!AREA2014A,3)) -> PLE 15mm | G23: HEB200 | H23: =IF(A23=0,"PESOU",+VLOOKUP(A23,[3]!AREA2014A,4))*$B$2 -> 117.75 | I23: =IF(A23=0,"CODIGO", +VLOOKUP(A23,[3]!AREA2014A,13)) -> 12.54.52.420.01 | J23: 5076 | K23: 200 | L23: 6.015 | M23: 6.02 | O23: 2 | P23: =O23*$P$21 -> 2 | Q23: =IF(K23="",+H23/1000*J23,+H23/1000*J23/1000*K23) -> 119.5398 | R23: =+Q23*O23 -> 239.0796 | S23: =+Q23*P23 -> 239.0796 | V23: =IF(U22>100,"EXTRAPESADO",IF(U22<=100,IF(U22>=60,"PESADO",IF(U22<60,IF(U22>=30,"MEDIANO","LIVIANO"))))) -> LIVIANO | AJ23: =IF(A23=0,"NORMA", +VLOOKUP(A23,[3]!AREA2014A,15)) -> A36 | AL23: =AL22 -> TCL2 | AM23: ;
A24: 979 | B24: =B21 -> 1 | D24: p4 | E24: PLACA | F24: =IF(A24=0,"SERIE",+VLOOKUP(A24,[3]!AREA2014A,3)) -> PLE 15mm | G24: PL10X144 | H24: =IF(A24=0,"PESOU",+VLOOKUP(A24,[3]!AREA2014A,4))*$B$2 -> 117.75 | I24: =IF(A24=0,"CODIGO", +VLOOKUP(A24,[3]!AREA2014A,13)) -> 12.54.52.420.00 | J24: 149 | K24: 144 | L24: 0.033 | M24: 0.07 | O24: 2 | P24: =O24*$P$21 -> 2 | Q24: =IF(K24="",+H24/1000*J24,+H24/1000*J24/1000*K24) -> 2.526444 | R24: =+Q24*O24 -> 5.052888 | S24: =+Q24*P24 -> 5.052888 | V24: =IF(U21>100,"EXTRAPESADO",IF(U21<=100,IF(U21>=60,"PESADO",IF(U21<60,IF(U21>=30,"MEDIANO","LIVIANO"))))) -> PESADO | AJ24: =IF(A24=0,"NORMA", +VLOOKUP(A24,[3]!AREA2014A,15)) -> A572 G50 | AL24: =AL22 -> TCL2 | AM24: ;
A25: 693 | B25: =B21 -> 1 | D25: pb1 | E25: PLACA BASE | F25: =IF(A25=0,"SERIE",+VLOOKUP(A25,[3]!AREA2014A,3)) -> PLE 20mm | G25: PL20X460 | H25: =IF(A25=0,"PESOU",+VLOOKUP(A25,[3]!AREA2014A,4))*$B$2 -> 157 | I25: =IF(A25=0,"CODIGO", +VLOOKUP(A25,[3]!AREA2014A,13)) -> 12.54.52.470.03 | J25: 460 | K25: 460 | L25: 0.46 | M25: 0.46 | O25: 1 | P25: =O25*$P$21 -> 1 | Q25: =IF(K25="",+H25/1000*J25,+H25/1000*J25/1000*K25) -> 33.2212 | R25: =+Q25*O25 -> 33.2212 | S25: =+Q25*P25 -> 33.2212 | V25: =IF(U21>100,"EXTRAPESADO",IF(U21<=100,IF(U21>=60,"PESADO",IF(U21<60,IF(U21>=30,"MEDIANO","LIVIANO"))))) -> PESADO | AJ25: =IF(A25=0,"NORMA", +VLOOKUP(A25,[3]!AREA2014A,15)) -> A36 | AL25: =AL24 -> TCL2 | AM25: ;
B26: 1 | C26: 5 | D26: TCL3 | E26: COLUMNA - HEB 300 | F26: =F27 -> PLE 12mm | G26: =G27 -> HEB300 | J26: =MAX(J27:J32) -> 5076 | N26: 10.2 | O26: 1 | P26: =O26*TOTALES!$A$1 -> 1 | Q26: =+R26 -> 698.9213 | R26: =SUM(R27:R32) -> 698.9213 | T26: =+R26*P26 -> 698.9213 | U26: =R26/(J26/1000) -> 137.69135 | V26: =IF(U26>100,"EXTRAPESADO",IF(U26<=100,IF(U26>=60,"PESADO",IF(U26<60,IF(U26>=30,"MEDIANO","LIVIANO"))))) -> EXTRAPESADO | AJ26: =AJ27 -> A36 | AL26: =D26 -> TCL3 | AM26: ;
A27: 687 | B27: =B26 -> 1 | D27: TCL3 | E27: ALMA | F27: =IF(A27=0,"SERIE",+VLOOKUP(A27,[3]!AREA2014A,3)) -> PLE 12mm | G27: HEB300 | H27: =IF(A27=0,"PESOU",+VLOOKUP(A27,[3]!AREA2014A,4))*$B$2 -> 94.2 | I27: =IF(A27=0,"CODIGO", +VLOOKUP(A27,[3]!AREA2014A,13)) -> 12.54.52.390.00 | J27: 5076 | K27: =300-40 -> 260 | L27: 9.054 | M27: 9.05 | O27: 1 | P27: =O27*$P$26 -> 1 | Q27: =IF(K27="",+H27/1000*J27,+H27/1000*J27/1000*K27) -> 124.32139 | R27: =+Q27*O27 -> 124.32139 | S27: =+Q27*P27 -> 124.32139 | V27: =IF(U26>100,"EXTRAPESADO",IF(U26<=100,IF(U26>=60,"PESADO",IF(U26<60,IF(U26>=30,"MEDIANO","LIVIANO"))))) -> EXTRAPESADO | AJ27: =IF(A27=0,"NORMA", +VLOOKUP(A27,[3]!AREA2014A,15)) -> A36 | AL27: =AL26 -> TCL3 | AM27: ;
A28: 693 | B28: =B27 -> 1 | D28: TCL3 | E28: PATIN | F28: =IF(A28=0,"SERIE",+VLOOKUP(A28,[3]!AREA2014A,3)) -> PLE 20mm | G28: HEB300 | H28: =IF(A28=0,"PESOU",+VLOOKUP(A28,[3]!AREA2014A,4))*$B$2 -> 157 | I28: =IF(A28=0,"CODIGO", +VLOOKUP(A28,[3]!AREA2014A,13)) -> 12.54.52.470.03 | J28: 5076 | K28: 300 | L28: 9.054 | M28: 9.05 | O28: 2 | P28: =O28*$P$26 -> 2 | Q28: =IF(K28="",+H28/1000*J28,+H28/1000*J28/1000*K28) -> 239.0796 | R28: =+Q28*O28 -> 478.1592 | S28: =+Q28*P28 -> 478.1592 | V28: =IF(U27>100,"EXTRAPESADO",IF(U27<=100,IF(U27>=60,"PESADO",IF(U27<60,IF(U27>=30,"MEDIANO","LIVIANO"))))) -> LIVIANO | AJ28: =IF(A28=0,"NORMA", +VLOOKUP(A28,[3]!AREA2014A,15)) -> A36 | AL28: =AL27 -> TCL3 | AM28: ;
A29: 693 | B29: =B26 -> 1 | D29: a3 | E29: PLACA | F29: =IF(A29=0,"SERIE",+VLOOKUP(A29,[3]!AREA2014A,3)) -> PLE 20mm | G29: PL20X143 | H29: =IF(A29=0,"PESOU",+VLOOKUP(A29,[3]!AREA2014A,4))*$B$2 -> 157 | I29: =IF(A29=0,"CODIGO", +VLOOKUP(A29,[3]!AREA2014A,13)) -> 12.54.52.470.03 | J29: 258 | K29: 143 | L29: 0.088 | M29: 0.35 | O29: 4 | P29: =O29*$P$26 -> 4 | Q29: =IF(K29="",+H29/1000*J29,+H29/1000*J29/1000*K29) -> 5.792358 | R29: =+Q29*O29 -> 23.169432 | S29: =+Q29*P29 -> 23.169432 | V29: =IF(U26>100,"EXTRAPESADO",IF(U26<=100,IF(U26>=60,"PESADO",IF(U26<60,IF(U26>=30,"MEDIANO","LIVIANO"))))) -> EXTRAPESADO | AJ29: =IF(A29=0,"NORMA", +VLOOKUP(A29,[3]!AREA2014A,15)) -> A36 | AL29: =AL27 -> TCL3 | AM29: ;
A30: 693 | B30: =B26 -> 1 | D30: a3 | E30: PLACA | F30: =IF(A30=0,"SERIE",+VLOOKUP(A30,[3]!AREA2014A,3)) -> PLE 20mm | G30: PL20X144 | H30: =IF(A30=0,"PESOU",+VLOOKUP(A30,[3]!AREA2014A,4))*$B$2 -> 157 | I30: =IF(A30=0,"CODIGO", +VLOOKUP(A30,[3]!AREA2014A,13)) -> 12.54.52.470.03 | J30: 258 | K30: 144 | L30: 0.089 | M30: 0.53 | O30: 6 | P30: =O30*$P$26 -> 6 | Q30: =IF(K30="",+H30/1000*J30,+H30/1000*J30/1000*K30) -> 5.832864 | R30: =+Q30*O30 -> 34.997184 | S30: =+Q30*P30 -> 34.997184 | V30: =IF(U26>100,"EXTRAPESADO",IF(U26<=100,IF(U26>=60,"PESADO",IF(U26<60,IF(U26>=30,"MEDIANO","LIVIANO"))))) -> EXTRAPESADO | AJ30: =IF(A30=0,"NORMA", +VLOOKUP(A30,[3]!AREA2014A,15)) -> A36 | AL30: =AL29 -> TCL3 | AM30: ;
A31: 979 | B31: =B26 -> 1 | D31: p1 | E31: PLACA | F31: =IF(A31=0,"SERIE",+VLOOKUP(A31,[3]!AREA2014A,3)) -> PLE 15mm | G31: PL10X144 | H31: =IF(A31=0,"PESOU",+VLOOKUP(A31,[3]!AREA2014A,4))*$B$2 -> 117.75 | I31: =IF(A31=0,"CODIGO", +VLOOKUP(A31,[3]!AREA2014A,13)) -> 12.54.52.420.00 | J31: 149 | K31: 144 | L31: 0.033 | M31: 0.07 | O31: 2 | P31: =O31*$P$26 -> 2 | Q31: =IF(K31="",+H31/1000*J31,+H31/1000*J31/1000*K31) -> 2.526444 | R31: =+Q31*O31 -> 5.052888 | S31: =+Q31*P31 -> 5.052888 | V31: =IF(U26>100,"EXTRAPESADO",IF(U26<=100,IF(U26>=60,"PESADO",IF(U26<60,IF(U26>=30,"MEDIANO","LIVIANO"))))) -> EXTRAPESADO | AJ31: =IF(A31=0,"NORMA", +VLOOKUP(A31,[3]!AREA2014A,15)) -> A572 G50 | AL31: =AL30 -> TCL3 | AM31: ;
A32: 693 | B32: =B26 -> 1 | D32: pb1 | E32: PLACA BASE | F32: =IF(A32=0,"SERIE",+VLOOKUP(A32,[3]!AREA2014A,3)) -> PLE 20mm | G32: PL20X460 | H32: =IF(A32=0,"PESOU",+VLOOKUP(A32,[3]!AREA2014A,4))*$B$2 -> 157 | I32: =IF(A32=0,"CODIGO", +VLOOKUP(A32,[3]!AREA2014A,13)) -> 12.54.52.470.03 | J32: 460 | K32: 460 | L32: 0.46 | M32: 0.46 | O32: 1 | P32: =O32*$P$26 -> 1 | Q32: =IF(K32="",+H32/1000*J32,+H32/1000*J32/1000*K32) -> 33.2212 | R32: =+Q32*O32 -> 33.2212 | S32: =+Q32*P32 -> 33.2212 | V32: =IF(U26>100,"EXTRAPESADO",IF(U26<=100,IF(U26>=60,"PESADO",IF(U26<60,IF(U26>=30,"MEDIANO","LIVIANO"))))) -> EXTRAPESADO | AJ32: =IF(A32=0,"NORMA", +VLOOKUP(A32,[3]!AREA2014A,15)) -> A36 | AL32: =AL31 -> TCL3 | AM32: ;
B33: 1 | C33: 6 | D33: TCL4 | E33: COLUMNA - HEB 300 | F33: =F34 -> PLE 12mm | G33: =G34 -> HEB300 | J33: =MAX(J34:J43) -> 5076 | N33: 11.3 | O33: 1 | P33: =O33*TOTALES!$A$1 -> 1 | Q33: =+R33 -> 764.46754 | R33: =SUM(R34:R43) -> 764.46754 | T33: =+R33*P33 -> 764.46754 | U33: =R33/(J33/1000) -> 150.60432 | V33: =IF(U33>100,"EXTRAPESADO",IF(U33<=100,IF(U33>=60,"PESADO",IF(U33<60,IF(U33>=30,"MEDIANO","LIVIANO"))))) -> EXTRAPESADO | AJ33: =AJ34 -> A36 | AL33: =D33 -> TCL4 | AM33: ;
A34: 687 | B34: =B33 -> 1 | D34: TCL4 | E34: ALMA | F34: =IF(A34=0,"SERIE",+VLOOKUP(A34,[3]!AREA2014A,3)) -> PLE 12mm | G34: HEB300 | H34: =IF(A34=0,"PESOU",+VLOOKUP(A34,[3]!AREA2014A,4))*$B$2 -> 94.2 | I34: =IF(A34=0,"CODIGO", +VLOOKUP(A34,[3]!AREA2014A,13)) -> 12.54.52.390.00 | J34: 5076 | K34: =300-40 -> 260 | L34: 9.054 | M34: 9.05 | O34: 1 | P34: =O34*$P$33 -> 1 | Q34: =IF(K34="",+H34/1000*J34,+H34/1000*J34/1000*K34) -> 124.32139 | R34: =+Q34*O34 -> 124.32139 | S34: =+Q34*P34 -> 124.32139 | V34: =IF(U33>100,"EXTRAPESADO",IF(U33<=100,IF(U33>=60,"PESADO",IF(U33<60,IF(U33>=30,"MEDIANO","LIVIANO"))))) -> EXTRAPESADO | AJ34: =IF(A34=0,"NORMA", +VLOOKUP(A34,[3]!AREA2014A,15)) -> A36 | AL34: =AL33 -> TCL4 | AM34: ;
A35: 693 | B35: =B34 -> 1 | D35: TCL4 | E35: PATIN | F35: =IF(A35=0,"SERIE",+VLOOKUP(A35,[3]!AREA2014A,3)) -> PLE 20mm | G35: HEB300 | H35: =IF(A35=0,"PESOU",+VLOOKUP(A35,[3]!AREA2014A,4))*$B$2 -> 157 | I35: =IF(A35=0,"CODIGO", +VLOOKUP(A35,[3]!AREA2014A,13)) -> 12.54.52.470.03 | J35: 5076 | K35: 300 | L35: 9.054 | M35: 9.05 | O35: 2 | P35: =O35*$P$33 -> 2 | Q35: =IF(K35="",+H35/1000*J35,+H35/1000*J35/1000*K35) -> 239.0796 | R35: =+Q35*O35 -> 478.1592 | S35: =+Q35*P35 -> 478.1592 | V35: =IF(U34>100,"EXTRAPESADO",IF(U34<=100,IF(U34>=60,"PESADO",IF(U34<60,IF(U34>=30,"MEDIANO","LIVIANO"))))) -> LIVIANO | AJ35: =IF(A35=0,"NORMA", +VLOOKUP(A35,[3]!AREA2014A,15)) -> A36 | AL35: =AL34 -> TCL4 | AM35: ;
A36: 979 | B36: =B33 -> 1 | D36: p1 | E36: PLACA | F36: =IF(A36=0,"SERIE",+VLOOKUP(A36,[3]!AREA2014A,3)) -> PLE 15mm | G36: PL10X144 | H36: =IF(A36=0,"PESOU",+VLOOKUP(A36,[3]!AREA2014A,4))*$B$2 -> 117.75 | I36: =IF(A36=0,"CODIGO", +VLOOKUP(A36,[3]!AREA2014A,13)) -> 12.54.52.420.00 | J36: 149 | K36: 144 | L36: 0.033 | M36: 0.07 | O36: 2 | P36: =O36*$P$33 -> 2 | Q36: =IF(K36="",+H36/1000*J36,+H36/1000*J36/1000*K36) -> 2.526444 | R36: =+Q36*O36 -> 5.052888 | S36: =+Q36*P36 -> 5.052888 | V36: =IF(U33>100,"EXTRAPESADO",IF(U33<=100,IF(U33>=60,"PESADO",IF(U33<60,IF(U33>=30,"MEDIANO","LIVIANO"))))) -> EXTRAPESADO | AJ36: =IF(A36=0,"NORMA", +VLOOKUP(A36,[3]!AREA2014A,15)) -> A572 G50 | AL36: =AL34 -> TCL4 | AM36: ;
A37: 693 | B37: =B33 -> 1 | D37: pb1 | E37: PLACA BASE | F37: =IF(A37=0,"SERIE",+VLOOKUP(A37,[3]!AREA2014A,3)) -> PLE 20mm | G37: PL20X460 | H37: =IF(A37=0,"PESOU",+VLOOKUP(A37,[3]!AREA2014A,4))*$B$2 -> 157 | I37: =IF(A37=0,"CODIGO", +VLOOKUP(A37,[3]!AREA2014A,13)) -> 12.54.52.470.03 | J37: 460 | K37: 460 | L37: 0.46 | M37: 0.46 | O37: 1 | P37: =O37*$P$33 -> 1 | Q37: =IF(K37="",+H37/1000*J37,+H37/1000*J37/1000*K37) -> 33.2212 | R37: =+Q37*O37 -> 33.2212 | S37: =+Q37*P37 -> 33.2212 | V37: =IF(U33>100,"EXTRAPESADO",IF(U33<=100,IF(U33>=60,"PESADO",IF(U33<60,IF(U33>=30,"MEDIANO","LIVIANO"))))) -> EXTRAPESADO | AJ37: =IF(A37=0,"NORMA", +VLOOKUP(A37,[3]!AREA2014A,15)) -> A36 | AL37: =AL36 -> TCL4 | AM37: ;
A38: 693 | B38: =B33 -> 1 | D38: pl7 | E38: ENDPLATE_1 | F38: =IF(A38=0,"SERIE",+VLOOKUP(A38,[3]!AREA2014A,3)) -> PLE 20mm | G38: PL20X250 | H38: =IF(A38=0,"PESOU",+VLOOKUP(A38,[3]!AREA2014A,4))*$B$2 -> 157 | I38: =IF(A38=0,"CODIGO", +VLOOKUP(A38,[3]!AREA2014A,13)) -> 12.54.52.470.03 | J38: 350 | K38: 250 | L38: 0.199 | M38: 0.2 | O38: 1 | P38: =O38*$P$33 -> 1 | Q38: =IF(K38="",+H38/1000*J38,+H38/1000*J38/1000*K38) -> 13.7375 | R38: =+Q38*O38 -> 13.7375 | S38: =+Q38*P38 -> 13.7375 | V38: =IF(U33>100,"EXTRAPESADO",IF(U33<=100,IF(U33>=60,"PESADO",IF(U33<60,IF(U33>=30,"MEDIANO","LIVIANO"))))) -> EXTRAPESADO | AJ38: =IF(A38=0,"NORMA", +VLOOKUP(A38,[3]!AREA2014A,15)) -> A36 | AL38: =AL37 -> TCL4 | AM38: ;
A39: 693 | B39: =B33 -> 1 | D39: pl8 | E39: PLACA | F39: =IF(A39=0,"SERIE",+VLOOKUP(A39,[3]!AREA2014A,3)) -> PLE 20mm | G39: PL20X259 | H39: =IF(A39=0,"PESOU",+VLOOKUP(A39,[3]!AREA2014A,4))*$B$2 -> 157 | I39: =IF(A39=0,"CODIGO", +VLOOKUP(A39,[3]!AREA2014A,13)) -> 12.54.52.470.03 | J39: 345 | K39: 259 | L39: 0.199 | M39: 0.8 | O39: 4 | P39: =O39*$P$33 -> 4 | Q39: =IF(K39="",+H39/1000*J39,+H39/1000*J39/1000*K39) -> 14.028735 | R39: =+Q39*O39 -> 56.11494 | S39: =+Q39*P39 -> 56.11494 | V39: =IF(U33>100,"EXTRAPESADO",IF(U33<=100,IF(U33>=60,"PESADO",IF(U33<60,IF(U33>=30,"MEDIANO","LIVIANO"))))) -> EXTRAPESADO | AJ39: =IF(A39=0,"NORMA", +VLOOKUP(A39,[3]!AREA2014A,15)) -> A36 | AL39: =AL38 -> TCL4 | AM39: ;
A40: 693 | B40: =B33 -> 1 | D40: pl9 | E40: PLACA | F40: =IF(A40=0,"SERIE",+VLOOKUP(A40,[3]!AREA2014A,3)) -> PLE 20mm | G40: PL20X145 | H40: =IF(A40=0,"PESOU",+VLOOKUP(A40,[3]!AREA2014A,4))*$B$2 -> 157 | I40: =IF(A40=0,"CODIGO", +VLOOKUP(A40,[3]!AREA2014A,13)) -> 12.54.52.470.03 | J40: 258 | K40: 145 | L40: 0.089 | M40: 0.36 | O40: 4 | P40: =O40*$P$33 -> 4 | Q40: =IF(K40="",+H40/1000*J40,+H40/1000*J40/1000*K40) -> 5.87337 | R40: =+Q40*O40 -> 23.49348 | S40: =+Q40*P40 -> 23.49348 | V40: =IF(U33>100,"EXTRAPESADO",IF(U33<=100,IF(U33>=60,"PESADO",IF(U33<60,IF(U33>=30,"MEDIANO","LIVIANO"))))) -> EXTRAPESADO | AJ40: =IF(A40=0,"NORMA", +VLOOKUP(A40,[3]!AREA2014A,15)) -> A36 | AL40: =AL39 -> TCL4 | AM40: ;
...

Sheet TOTALES
A1: 1

Sheet Lista de Articulos
A1: POSICION | B1: Arriostramientos_2C | C1: Arriostramientos_4PL | D1: Arriostramientos_H_I
A2: Arriostramientos_2C | B2: a | C2: 1 | D2: Q
A3: Arriostramientos_4PL | B3: b | C3: 2 | D3: W
A4: Arriostramientos_H_I | B4: c | C4: 3 | D4: E
A5: Arriostramientos Perfiles Laminados | B5: d | C5: 4 | D5: R
A6: Base estructural
A7: Campers
A8: Celosías
A9: Columna 2C
A10: Columna 4PL
A11: Columna H, I
A12: Columna Perfil Laminado
A13: Columna Perfiles Laminados
A14: Columna Tipo Celosía
A15: Correas
A16: Diagonales
A17: Dovelas H, I
... A128: Tuberías de presión

Sheet BODEGAS
G1: CON ACABADO SUPERFICIAL | L1: SIN ACABADO SUPERFICIAL | Q1: Acabado Superficial
A2: SALIDA DE MATERIAL | B2: NUMERO | D2: INGRESA A LA BODEGA | E2: NUMERO | G2: PINTURA | H2: SECTOR | I2: # SECTOR | J2: BODEGA | L2: PINTURA | M2: SECTOR | N2: # SECTOR | O2: NUMERO | Q2: GALVANIZADO | R2: PINTADO
A3: MATERIA PRIMA | B3: 003 | D3: Producto en proceso en negro | E3: 900 | G3: ACABADO | H3: ELECTRICO | I3: 11 | J3: 970 | L3: NEGRO | M3: ELECTRICO | N3: 11 | O3: 950 | Q3: EXTRA GALVANIZADO | R3: PINTADO
G4: ACABADO | H4: TELECOMUNICACIONES | I4: 12 | J4: 971 | L4: NEGRO | M4: TELECOMUNICACIONES | N4: 12 | O4: 951 | Q4: NEGRO | R4: NEGRO
G5: ACABADO | H5: INF. SIERRA | I5: 16 | J5: 972 | L5: NEGRO | M5: INF. SIERRA | N5: 16 | O5: 952 | Q5: BICAPA EPOXICO-EPOXICO | R5: PINTADO
A6: Proyecto | B6: Sector | E6: Tipo ACS | G6: ACABADO | H6: PETROLEO | I6: 14 | J6: 973 | L6: NEGRO | M6: PETROLEO | N6: 14 | O6: 953 | Q6: BICAPA EPOXICO-POLUIRETANO | R6: PINTADO
A7: ='ORDENES DE FABRICACION'!#REF! -> #REF! | B7: =VALUE(LEFT(A7,2)) -> #REF! | E7: =VLOOKUP('ORDENES DE FABRICACION'!AK6,$Q$2:$R$17,2,FALSE) -> #N/A | G7: ACABADO | H7: BANDEJAS | J7: 974 | L7: NEGRO | M7: BANDEJAS | O7: 954 | Q7: BICAPA EPOXICO-SINTETICO | R7: PINTADO
A8: TRUE | G8: ACABADO | H8: INF. COSTA | I8: 17 | J8: 975 | L8: NEGRO | M8: INF. COSTA | N8: 17 | O8: 955 | Q8: BICAPA WASHPRIMER-SINTETICO | R8: PINTADO
A9: FALSE | G9: ACABADO | H9: GALVANIZADO | J9: 976 | L9: NEGRO | M9: SERVICIO A TERCEROS | O9: 956 | Q9: DUPLEX-ACRILICO | R9: PINTADO
G10: ACABADO | H10: CONSUMO INTERNO | J10: 978 | L10: NEGRO | M10: CONSUMO INTERNO | O10: 958 | Q10: DUPLEX ESMALTE | R10: PINTADO
G11: ACABADO | H11: CMG | I11: 13 | J11: 975 | L11: NEGRO | M11: CMG | N11: 13 | O11: 955
Q12: BICAPA ANTICORROSIVO-SINTETICO | R12: PINTADO
Q13: MONO CAPA ANTICORROSIVO | R13: PINTADO
A14: Bodega Entrada | Q14: BICAPA EPOXICO-ACRILICO | R14: PINTADO
A15: =IF(E7="PINTADO",VLOOKUP(B7,I3:J11,2,FALSE),IF(E7="NEGRO",VLOOKUP(B7,BODEGAS!$N$3:$O$11,2,FALSE),976)) -> #N/A | Q15: TRICAPA INORGANICO DE ZINC-EPOXICO-POLUIRETANO | R15: PINTADO
Q16: MONO CAPA EPOXICO | R16: PINTADO
Q17: TRICAPA ORGANICO DE ZINC-EPOXICO-POLUIRETANO | R17: PINTADO
P20: =_xlfn.IFS(AND((C7=11)*(E7="NEGRO")),O3,((C7=11)*(E7="GALVANIZADO")),J3,((C7=11)*(E7="PINTADO")),J3,((C7=12)*(E7="NEGRO")),O4,((C7=12)*(E7="GALVANIZADO")),J4,((C7=12)*(E7="PINTADO")),J4,((C7=16)*(E7="NEGRO")),O5,((C7=16)*(E7="GALVANIZADO")),J5,((C7=16)*(E7="PINTADO")),J5,((C7=14)*(E7="NEGRO")),O6,((C7=14)*(E7="GALVANIZADO")),J6,((C7=14)*(E7="PINTADO")),J6,((C7=17)*(E7="NEGRO")),O8,((C7=17)*(E7="GALVANIZADO")),J8,((C7=17)*(E7="PINTADO")),J8) -> #NAME?

Sheet RUTAS
A1: ÍTEM | B1: FAMILIA | C1: ELEMENTO | D1: DESCRIPCIÓN | E1: NOMBRE TEKLA | F1: OBSERBACIONES | G1: NOMBRE TEKLA (PARTES) | H1: RUTA | I1: NOMBRE COMPLETO | N1: CONJUNTOS | O1: RUTA
A2: 1 | B2: FLEJES | C2: ALMA | E2: ALMA | G2: ALMA | H2: 2000 | I2: ALMA | J2: 1 | L2: ESTRUCTURA PRINCIPAL | N2: COLUMNA HI | O2: 180
A3: =A2+1 -> 2 | B3: FLEJES | C3: ALMA | D3: CON PERFORACIONES | E3: ALMA CON PERFORACIONES | G3: ALMA PERF | H3: 2010 | I3: ALMA PERFORADA | J3: 2 | L3: ESTRUCTURA PRINCIPAL | N3: COLUMNA 2C | O3: 186
A4: =A3+1 -> 3 | B4: FLEJES | C4: ALMA | D4: CON BISEL | E4: ALMA CON BISEL | G4: ALMA BISEL | H4: 2033 | I4: ALMA BISELADA | J4: 3 | L4: ESTRUCTURA PRINCIPAL | N4: COLUMNA 2G | O4: 180
A5: =A4+1 -> 4 | B5: FLEJES | C5: ALMA | D5: CON PERFORACIÓN - BISEL | E5: ALMA CON PERFORACIÓN - BISEL | G5: ALMA PER BISEL | H5: 2065 | I5: ALMA PERFORADA BISELADA | J5: 4 | L5: ESTRUCTURA PRINCIPAL | N5: COLUMNA LAM | O5: 180
A6: =A5+1 -> 5 | E6: PATIN | G6: PATIN | H6: 2000 | I6: PATINES | J6: 5 | L6: ESTRUCTURA PRINCIPAL | N6: COLUMNA CELOSIA | O6: 180
A7: =A6+1 -> 6 | B7: FLEJES | C7: PATÍN | E7: PATÍN SUPERIOR | G7: P.SUP | H7: 2000 | I7: PATIN SUPERIOR | J7: 6 | L7: ESTRUCTURA PRINCIPAL | N7: V.PRINCIPAL HI | O7: 180
A8: =A7+1 -> 7 | E8: PATÍN INFERIOR | G8: P.INF | H8: 2000 | I8: PATIN INFERIOR | J8: 7 | L8: ESTRUCTURA PRINCIPAL | N8: V.PRINCIPAL 2C | O8: 186
A9: =A8+1 -> 8 | E9: PATIN CON PERFORACIONES | G9: P.PERF | H9: 2010 | I9: PATINES PERFORADOS | J9: 8 | L9: ESTRUCTURA PRINCIPAL | N9: V.PRINCIPAL LAM | O9: 180
A10: =A9+1 -> 9 | B10: FLEJES | C10: PATÍN | D10: CON PERFORACIONES | E10: PATÍN SUPERIOR CON PERFORACIONES | G10: P.SUP PERF | H10: 2010 | I10: PATIN SUPERIOR PERFORADOS | J10: 9 | L10: ESTRUCTURA PRINCIPAL | N10: V.CELOSIA | O10: 180
A11: =A10+1 -> 10 | E11: PATÍN INFERIOR CON PERFORACIONES | G11: P.INF PERF | H11: 2010 | I11: PATIN INFERIOR PERFORADOS | J11: 10 | L11: ESTRUCTURA PRINCIPAL | N11: V.SECUNDARIA HI | O11: 180
A12: =A11+1 -> 11 | E12: PATIN CON BISEL | G12: P.BISEL | H12: 2033 | I12: PATINES BISELADOS | J12: 11 | L12: ESTRUCTURA PRINCIPAL | N12: V.SECUNDARIA 2C | O12: 186
A13: =A12+1 -> 12 | E13: PATÍN SUPERIOR CON BISEL | G13: P.SUP BISEL | H13: 2033 | I13: PATIN SUPERIOS BISELADOS | J13: 12 | L13: ESTRUCTURA PRINCIPAL | N13: V.SECUNDARIA LAM | O13: 180
A14: =A13+1 -> 13 | B14: FLEJES | C14: PATÍN | D14: CON BISEL | E14: PATÍN INFERIOR CON BISEL | G14: P.INF BISEL | H14: 2033 | I14: PATIN INFERIOR BISELADOS | J14: 13 | L14: ESTRUCTURA PRINCIPAL | N14: RIOSTRA HI | O14: 180
A15: =A14+1 -> 14 | E15: PATIN CON PERFORACIONES - BISEL | G15: P.PERF BISEL | H15: 2065 | I15: PATINES PERFORADOS BISELADOS | J15: 14 | L15: ESTRUCTURA PRINCIPAL | N15: RIOSTRA 2C | O15: 186
A16: =A15+1 -> 15 | E16: PATÍN SUPERIOR CON PERFORACIÓN - BISEL | G16: P.SUP PERF BISEL | H16: 2065 | I16: PATIN SUPERIOR PERFORADOS BISELADOS | J16: 15 | L16: ESTRUCTURA PRINCIPAL | N16: RIOSTRA PERFIL LAM | O16: 180
A17: =A16+1 -> 16 | B17: FLEJES | C17: PATÍN | D17: CON PERFORACIÓN - BISEL | E17: PATÍN INFERIOR CON PERFORACIÓN - BISEL | G17: P.INF PERF BISEL | H17: 2065 | I17: PATIN INFERIOR PERFORADOS BISELADOS | J17: 16 | L17: ESTRUCTURA PRINCIPAL | N17: CORREA | O17: 180
A18: =A17+1 -> 17 | B18: FLEJES | C18: BARREDERA | E18: BARREDERA | G18: BARREDERA | H18: 2000 | I18: BARREDERA | J18: 17 | L18: ESTRUCTURA PRINCIPAL | N18: COLUMNA 4PL | O18: 186
A19: =A18+1 -> 18 | B19: FLEJES | C19: BARREDERA | D19: CON DOBLEZ | E19: BARREDERA CON DOBLEZ | G19: BARREDERA DOBLADA | H19: 2020 | I19: BARREDERA DOBLADA | J19: 18 | L19: ESTRUCTURA PRINCIPAL | N19: COLUMNA HI | O19: 180
A20: =A19+1 -> 19 | B20: FLEJES | C20: PLACA DE RESPALDO | E20: PLACA DE RESPALDO | G20: PL.RESPALDO | H20: 2000 | I20: PLACA RESPALDO | J20: 19 | L20: ESTRUCTURA PRINCIPAL | N20: COLUMNA 2C | O20: 186
A21: 21 | B21: PLACA | C21: PLACA DE CONEXIÓN | G21: PL.PERF | H21: 2010 | I21: PLACA PERFORADA | J21: 23 | L21: ESTRUCTURA PRINCIPAL | N21: COLUMNA LAM | O21: 180
A22: =A21+1 -> 22 | G22: PLACA | H22: 2000 | I22: PLACA | J22: 24 | L22: ESTRUCTURA PRINCIPAL | N22: COLUMNA CELOSIA | O22: 180
A23: =A22+1 -> 23 | G23: PL.PLEGADA PERF | H23: 2050 | I23: PLACA PLEGADA PERFORADA | J23: 25 | L23: ESTRUCTURA PRINCIPAL | N23: V.PRINCIPAL 4PL | O23: 186
A24: =A23+1 -> 24 | G24: PL.PLEGADA | H24: 2020 | I24: PLACA PLEGADA | J24: 26 | L24: ESTRUCTURA PRINCIPAL | N24: V.PRINCIPAL HI | O24: 180
A25: 25 | B25: PLACA | C25: BRIDAS | E25: BRIDAS | G25: BRIDAS | H25: 2000 | I25: BRIDAS | J25: 28 | L25: ESTRUCTURA PRINCIPAL | N25: V.PRINCIPAL 2C | O25: 186
A26: =A25+1 -> 26 | B26: PLACA | C26: RIGIDIZADOR | E26: RIGIDIZADOR | G26: RIGIDIZADOR | H26: 2000 | I26: RIGIDIZADOR | J26: 29 | L26: ESTRUCTURA PRINCIPAL | N26: V.PRINCIPAL LAM | O26: 180
A27: 27 | C27: PLACAS PISO | D27: CON PERFORACIÓN - AVELLANADO | E27: PLACAS PISO CON PERFORACIÓN - AVELLANADO | G27: PL.PISO AVELLANADO | H27: 2010 | I27: PLACA PISO PERFORADO Y AVELLANADO | J27: 31 | L27: ESTRUCTURA PRINCIPAL | N27: V.CELOSIA | O27: 180
A28: 28 | E28: PERFIL L CON PERFORACIONES | G28: A.PERF | H28: 2010 | I28: ANGULO PERFORADO | J28: 34 | L28: ESTRUCTURA PRINCIPAL | N28: V.SECUNDARIA 4PL | O28: 186
A29: =A28+1 -> 29 | E29: PERFIL L SIN PERFORACIONES | G29: ANGULO | H29: 2000 | I29: ANGULO SIN PERFORACION | J29: 35 | L29: ESTRUCTURA PRINCIPAL | N29: V.SECUNDARIA HI | O29: 180
A30: =A29+1 -> 30 | E30: PERFIL L SIN PERFORACIONES | G30: A.PERF DOBLEZ | H30: 2050 | I30: ANGULO PERFORADO DOBLADO | J30: 36 | L30: ESTRUCTURA PRINCIPAL | N30: V.SECUNDARIA 2C | O30: 186
A31: =A30+1 -> 31 | E31: PERFIL L SIN PERFORACIONES | G31: A.PERF DOBLEZ DESP | H31: 2050 | I31: ANGULO PERFORADO DOBLADO DESPUNTADO | J31: 37 | L31: ESTRUCTURA PRINCIPAL | N31: V.SECUNDARIA LAM | O31: 180
A32: =A31+1 -> 32 | E32: PERFIL L SIN PERFORACIONES | G32: A.PERF DOB DESP DEST | H32: 2050 | I32: ANGULO PERFORADO DOBLADO DESPUNTADO DESTALONADO | J32: 38 | L32: ESTRUCTURA PRINCIPAL | N32: RIOSTRA 4PL | O32: 186
A33: =A32+1 -> 33 | E33: PERFIL L SIN PERFORACIONES | G33: A.PERF DEST | H33: 2010 | I33: ANGULO PERFORADO DESTALONADO | J33: 39 | L33: ESTRUCTURA PRINCIPAL | N33: RIOSTRA HI | O33: 180
A34: =A33+1 -> 34 | B34: PERFILES | C34: PERFIL C | E34: PERFIL C | G34: PERFIL C | H34: 2000 | I34: PERFIL LAMINADO C | J34: 40 | L34: ESTRUCTURA PRINCIPAL | N34: RIOSTRA 2C | O34: 186
A35: =A34+1 -> 35 | B35: PERFILES | C35: PERFIL C | D35: CON PERFORACIÓN | E35: PERFIL C CON PERFORACIÓN | G35: PERFIL C PERF | H35: 2010 | I35: PERFIL C PERFORADO | J35: 41 | L35: ESTRUCTURA PRINCIPAL | N35: RIOSTRA PERFIL LAM | O35: 180
A36: =A35+1 -> 36 | B36: PERFILES | C36: PERFIL G | E36: PERFIL G | G36: PERFIL G | H36: 2000 | I36: PERFIL LAMINADO G | J36: 42 | L36: ESTRUCTURA PRINCIPAL | N36: CORREA | O36: 180
A37: =A36+1 -> 37 | B37: PERFILES | C37: PERFIL G | D37: CON PERFORACIÓN | E37: PERFIL G CON PERFORACIÓN | G37: PERFIL G PERF | H37: 2010 | I37: PERFIL G PERFORADO | J37: 43 | L37: ESTRUCTURA PRINCIPAL | N37: COLUMNA 4PL | O37: 186
A38: =A37+1 -> 38 | B38: PERFILES | C38: PERFIL Z | E38: PERFIL Z | G38: PERFIL Z | H38: 2010 | I38: PERFIL LAMINADO Z | J38: 44 | L38: ESTRUCTURA PRINCIPAL | N38: COLUMNA HI | O38: 180
A39: =A38+1 -> 39 | B39: PERFILES | C39: PERFIL Z | D39: CON PERFORACIÓN | E39: PERFIL Z CON PERFORACIÓN | G39: PERFIL Z PERF | H39: 2010 | I39: PERFIL Z PERFORADO | J39: 45 | L39: ESTRUCTURA PRINCIPAL | N39: COLUMNA 2C | O39: 186
A40: =A39+1 -> 40 | B40: PERFILES | C40: PERFIL HEA | E40: PERFIL HEA | G40: PERFIL HEA | H40: 2000 | I40: PERFIL LAMINADO HEA | J40: 46 | L40: ESTRUCTURA PRINCIPAL | N40: COLUMNA LAM | O40: 180
...
